<?xml version="1.0"?>
<robot name="my_robot">

  <link name="base">
    <inertial>
      <!-- COM: (0.0, 0.0, 34.8912) mm -->
      <origin xyz="0 0 0.0348912" rpy="0 0 0"/>
      <mass value="0.6248"/>
      <inertia ixx="0.0021425" ixy="0.0" ixz="0.0"
               iyy="0.0020799" iyz="0.0"
               izz="0.0030294"/>
    </inertial>
    <visual>
      <geometry>
        <mesh filename="package://sim/meshes/base.stl" scale="0.001 0.001 0.001"/>
      </geometry>
    </visual>
    <collision>
      <geometry>
        <mesh filename="package://sim/meshes/base.stl" scale="0.001 0.001 0.001"/>
      </geometry>
    </collision>
  </link>

  <link name="rs02_1">
    <inertial>
      <origin xyz="0 0 -0.0183" rpy="0 0 0"/>
      <mass value="0.4116"/>
      <inertia ixx="2.7445939353e-04" ixy="-2.6756294195e-08" ixz="-1.3613583610e-08"
               iyy="2.7390454989e-04" iyz="-1.9869231612e-07"
               izz="2.8680150761e-04"/>
    </inertial>
    <visual>
      <geometry>
        <mesh filename="package://sim/meshes/RS02(0.0.0).stl" scale="0.001 0.001 0.001"/>
      </geometry>
    </visual>
    <collision>
      <geometry>
        <mesh filename="package://sim/meshes/RS02(0.0.0).stl" scale="0.001 0.001 0.001"/>
      </geometry>
    </collision>
  </link>

  <link name="rs02_2">
    <inertial>
      <origin xyz="0 0 -0.0183" rpy="0 0 0"/>
      <mass value="0.4116"/>
      <inertia ixx="2.7445939353e-04" ixy="-2.6756294195e-08" ixz="-1.3613583610e-08"
               iyy="2.7390454989e-04" iyz="-1.9869231612e-07"
               izz="2.8680150761e-04"/>
    </inertial>
    <visual>
      <geometry>
        <mesh filename="package://sim/meshes/RS02(0.0.0).stl" scale="0.001 0.001 0.001"/>
      </geometry>
    </visual>
    <collision>
      <geometry>
        <mesh filename="package://sim/meshes/RS02(0.0.0).stl" scale="0.001 0.001 0.001"/>
      </geometry>
    </collision>
  </link>

  <link name="rs02_3">
    <inertial>
      <origin xyz="0 0 -0.0183" rpy="0 0 0"/>
      <mass value="0.4116"/>
      <inertia ixx="2.7445939353e-04" ixy="-2.6756294195e-08" ixz="-1.3613583610e-08"
               iyy="2.7390454989e-04" iyz="-1.9869231612e-07"
               izz="2.8680150761e-04"/>
    </inertial>
    <visual>
      <geometry>
        <mesh filename="package://sim/meshes/RS02(0.0.0).stl" scale="0.001 0.001 0.001"/>
      </geometry>
    </visual>
    <collision>
      <geometry>
        <mesh filename="package://sim/meshes/RS02(0.0.0).stl" scale="0.001 0.001 0.001"/>
      </geometry>
    </collision>
  </link>

  <link name="rs03">
    <inertial>
      <origin xyz="0 0 -0.0215" rpy="0 0 0"/>
      <mass value="0.9244"/>
      <inertia ixx="8.7181026538e-04" ixy="-6.3224012508e-07" ixz="-7.1639989689e-06"
               iyy="9.1644943246e-04" iyz="-1.1771250450e-06"
               izz="1.1953222120e-03"/>
    </inertial>
    <visual>
      <geometry>
        <mesh filename="package://sim/meshes/RS03(0.0.0).stl" scale="0.001 0.001 0.001"/>
      </geometry>
    </visual>
    <collision>
      <geometry>
        <mesh filename="package://sim/meshes/RS03(0.0.0).stl" scale="0.001 0.001 0.001"/>
      </geometry>
    </collision>
  </link>

  <link name="joint1">
    <inertial>
      <!-- COM: (0.0103, -14.2659, 57.9402) mm -->
      <origin xyz="0.0000103 -0.0142659 0.0579402" rpy="0 0 0"/>
      <mass value="0.270398"/>
      <inertia ixx="0.00081368" ixy="0.0" ixz="0.0"
               iyy="0.00104368" iyz="0.0"
               izz="0.00081949"/>
    </inertial>
    <visual>
      <geometry>
        <mesh filename="package://sim/meshes/joint1.stl" scale="0.001 0.001 0.001"/>
      </geometry>
    </visual>
    <collision>
      <geometry>
        <mesh filename="package://sim/meshes/joint1.stl" scale="0.001 0.001 0.001"/>
      </geometry>
    </collision>
  </link>

  <link name="link1_1">
    <inertial>
      <!-- COM: (0.0, 12.1112, 43.0994) mm -->
      <origin xyz="0 0.0121112 0.0430994" rpy="0 0 0"/>
      <mass value="0.236296"/>
      <inertia ixx="0.00039409" ixy="0.0" ixz="0.0"
               iyy="0.00035378" iyz="0.0"
               izz="0.00043232"/>
    </inertial>
    <visual>
      <geometry>
        <mesh filename="package://sim/meshes/link1_1.stl" scale="0.001 0.001 0.001"/>
      </geometry>
    </visual>
    <collision>
      <geometry>
        <mesh filename="package://sim/meshes/link1_1.stl" scale="0.001 0.001 0.001"/>
      </geometry>
    </collision>
  </link>

  <link name="link1_2">
    <inertial>
      <!-- COM: (0.0, 0.0, 150.0000) mm -->
      <origin xyz="0 0 0.15" rpy="0 0 0"/>
      <mass value="0.508299975"/>
      <inertia ixx="0.003890759307" ixy="0.0" ixz="0.0"
               iyy="0.003890759307" iyz="0.0"
               izz="0.000157018996"/>
    </inertial>
    <visual>
      <geometry>
        <mesh filename="package://sim/meshes/link1_2.stl" scale="0.001 0.001 0.001"/>
      </geometry>
    </visual>
    <collision>
      <geometry>
        <mesh filename="package://sim/meshes/link1_2.stl" scale="0.001 0.001 0.001"/>
      </geometry>
    </collision>
  </link>

  <link name="link1_3">
    <inertial>
      <!-- COM: (0.0002, 15.5124, 33.9681) mm -->
      <origin xyz="0.0000002 0.0155124 0.0339681" rpy="0 0 0"/>
      <mass value="0.279149934"/>
      <inertia ixx="0.000661231823" ixy="-0.000000001550" ixz="0.000000001529"
               iyy="0.000687897169" iyz="0.000125413257"
               izz="0.000472960204"/>
    </inertial>
    <visual>
      <geometry>
        <mesh filename="package://sim/meshes/link1_3.stl" scale="0.001 0.001 0.001"/>
      </geometry>
    </visual>
    <collision>
      <geometry>
        <mesh filename="package://sim/meshes/link1_3.stl" scale="0.001 0.001 0.001"/>
      </geometry>
    </collision>
  </link>

  <link name="link2_1">
    <inertial>
      <!-- COM: (0.0031, -10.0157, 43.8699) mm -->
      <origin xyz="0.0000031 -0.0100157 0.0438699" rpy="0 0 0"/>
      <mass value="0.151798"/>
      <inertia ixx="0.00026036" ixy="0.0" ixz="0.0"
               iyy="0.00033758" iyz="0.0"
               izz="0.00027115"/>
    </inertial>
    <visual>
      <geometry>
        <mesh filename="package://sim/meshes/link2_1.stl" scale="0.001 0.001 0.001"/>
      </geometry>
    </visual>
    <collision>
      <geometry>
        <mesh filename="package://sim/meshes/link2_1.stl" scale="0.001 0.001 0.001"/>
      </geometry>
    </collision>
  </link>

  <link name="link2_2">
    <inertial>
      <!-- COM: (0.0354, -0.0354, 29.1096) mm -->
      <origin xyz="0.0000354 -0.0000354 0.0291096" rpy="0 0 0"/>
      <mass value="0.112000"/>
      <inertia ixx="0.00009821" ixy="0.0" ixz="0.0"
               iyy="0.00009821" iyz="0.0"
               izz="0.00011208"/>
    </inertial>
    <visual>
      <geometry>
        <mesh filename="package://sim/meshes/link2_2.stl" scale="0.001 0.001 0.001"/>
      </geometry>
    </visual>
    <collision>
      <geometry>
        <mesh filename="package://sim/meshes/link2_2.stl" scale="0.001 0.001 0.001"/>
      </geometry>
    </collision>
  </link>

  <link name="link2_3">
    <inertial>
      <!-- COM: (0.0, 0.0, 115.0000) mm -->
      <origin xyz="0 0 0.115" rpy="0 0 0"/>
      <mass value="0.170500037"/>
      <inertia ixx="0.000759754048" ixy="0.0" ixz="0.0"
               iyy="0.000759754048" iyz="0.0"
               izz="0.000052564816"/>
    </inertial>
    <visual>
      <geometry>
        <mesh filename="package://sim/meshes/link2_3.stl" scale="0.001 0.001 0.001"/>
      </geometry>
    </visual>
    <collision>
      <geometry>
        <mesh filename="package://sim/meshes/link2_3.stl" scale="0.001 0.001 0.001"/>
      </geometry>
    </collision>
  </link>

  <!-- joints -->
  <joint name="m1" type="fixed">
    <parent link="base"/>
    <child  link="rs02_1"/>
    <origin xyz="0 0 0.1002" rpy="0 0 0"/>
  </joint>

  <joint name="j1" type="revolute">
    <parent link="rs02_1"/>
    <child  link="joint1"/>
    <origin xyz="0 0 0" rpy="3.14159 0 0"/>
    <axis xyz="0 0 1"/>
    <limit lower="-3.14159" upper="3.14159" effort="50" velocity="100"/>
  </joint>

  <joint name="m2" type="fixed">
    <parent link="joint1"/>
    <child  link="rs03"/>
    <origin xyz="-0.0362 0 -0.0893" rpy="1.5708 0 -1.5708"/>
  </joint>

  <joint name="j2" type="revolute">
    <parent link="rs03"/>
    <child  link="link1_1"/>
    <origin xyz="0 0 0" rpy="3.1415926 0 0"/>
    <axis xyz="0 0 1"/>
    <limit lower="-1.78" upper="1.78" effort="50" velocity="100"/>
  </joint>

  <joint name="j2_2" type="fixed">
    <parent link="link1_1"/>
    <child  link="link1_2"/>
    <origin xyz="0 0.05 -0.05715" rpy="-1.5708 0 0"/>
  </joint>

  <joint name="j2_3" type="fixed">
    <parent link="link1_2"/>
    <child  link="link1_3"/>
    <origin xyz="0 0 0.3" rpy="0 0 3.1415926"/>
  </joint>

  <joint name="m3" type="fixed">
    <parent link="link1_3"/>
    <child  link="rs02_2"/>
    <origin xyz="0 0.06735 0.050" rpy="-1.5708 0 0"/>
  </joint>

  <joint name="j3" type="revolute">
    <parent link="rs02_2"/>
    <child  link="link2_1"/>
    <origin xyz="0 0 0" rpy="3.1415926 0 3.1415926"/>
    <axis xyz="0 0 1"/>
    <limit lower="-3.14159" upper="3.14159" effort="50" velocity="100"/>
  </joint>

  <joint name="j3_2" type="fixed">
    <parent link="link2_1"/>
    <child  link="link2_2"/>
    <origin xyz="0 -0.050 -0.05315" rpy="1.5708 0 0"/>
  </joint>

  <joint name="j3_3" type="fixed">
    <parent link="link2_2"/>
    <child  link="link2_3"/>
    <origin xyz="0 0 0.23" rpy="0 0 0"/>
  </joint>

  <joint name="j4" type="revolute">
    <parent link="link2_3"/>
    <child  link="rs02_3"/>
    <origin xyz="0 -0.06185 0.05" rpy="1.5708 0 0"/>
    <axis xyz="0 0 1"/>
    <limit lower="-3.14159" upper="3.14159" effort="50" velocity="100"/>
  </joint>

  <link name="ee_link"/>

  <joint name="ee_fixed" type="fixed">
    <parent link="link2_3"/>
    <child  link="ee_link"/>
    <origin xyz="0 0 0.23" rpy="0 0 0"/>
  </joint>

</robot>
