<?xml version="1.0" ?>
<mujoco model="my_robot">
  <compiler angle="radian" coordinate="local" meshdir="meshes" autolimits="true" inertiafromgeom="false"/>
  <option timestep="0.001" gravity="0 0 -9.81" integrator="RK4"/>
  <statistic center="0 0 0.4" extent="1.0"/>
  <default>
    <joint damping="0.02" armature="0.001" limited="true"/>
    <geom solimp="0.9 0.95 0.001" solref="0.02 1"/>
    <default class="visual">
      <geom contype="0" conaffinity="0" group="1" rgba="0.8 0.82 0.85 1"/>
    </default>
    <default class="collision">
      <geom group="3" rgba="0.8 0.82 0.85 0.25"/>
    </default>
  </default>
  <asset>
    <mesh name="base" file="base.stl" scale="0.001 0.001 0.001"/>
    <mesh name="RS02_0_0_0" file="RS02(0.0.0).stl" scale="0.001 0.001 0.001"/>
    <mesh name="RS03_0_0_0" file="RS03(0.0.0).stl" scale="0.001 0.001 0.001"/>
    <mesh name="RS00" file="RS00.stl" scale="0.001 0.001 0.001"/>
    <mesh name="RS05" file="RS05.stl" scale="0.001 0.001 0.001"/>
    <mesh name="joint1" file="joint1.stl" scale="0.001 0.001 0.001"/>
    <mesh name="link1_1" file="link1_1.stl" scale="0.001 0.001 0.001"/>
    <mesh name="link1_2" file="link1_2.stl" scale="0.001 0.001 0.001"/>
    <mesh name="link1_3" file="link1_3.stl" scale="0.001 0.001 0.001"/>
    <mesh name="link2_1" file="link2_1.stl" scale="0.001 0.001 0.001"/>
    <mesh name="link2_2" file="link2_2.stl" scale="0.001 0.001 0.001"/>
    <mesh name="link2_3" file="link2_3.stl" scale="0.001 0.001 0.001"/>
    <mesh name="link3_1" file="link3_1.stl" scale="0.001 0.001 0.001"/>
    <mesh name="link3_2" file="link3_2.stl" scale="0.001 0.001 0.001"/>
    <mesh name="connect_00" file="connect_00.stl" scale="0.001 0.001 0.001"/>
    <mesh name="connect_05" file="connect_05.stl" scale="0.001 0.001 0.001"/>
    <mesh name="case" file="case.stl" scale="0.001 0.001 0.001"/>
    <mesh name="gripper" file="gripper.stl" scale="0.001 0.001 0.001"/>
    <mesh name="finger_r" file="finger_r.stl" scale="0.001 0.001 0.001"/>
    <mesh name="finger_l" file="finger_l.stl" scale="0.001 0.001 0.001"/>
  </asset>
  <worldbody>
    <light name="top_light" pos="0 0 1.5" dir="0 0 -1" diffuse="0.8 0.8 0.8"/>
    <geom name="floor" type="plane" size="1 1 0.02" rgba="0.45 0.45 0.45 1"/>
    <body name="base">
      <inertial pos="0 0 0.0348912" mass="0.6248" fullinertia="0.0021425 0.0020799 0.0030294 0 0 0"/>
      <geom name="base_visual_0" class="visual" type="mesh" mesh="base"/>
      <geom name="base_collision_0" class="collision" type="mesh" mesh="base"/>
      <body name="rs02_1" pos="0 0 0.1002" quat="1 0 0 0">
        <inertial pos="0 0 -0.0183" mass="0.4116" fullinertia="0.0002744593935 0.0002739045499 0.0002868015076 -2.67562942e-08 -1.361358361e-08 -1.986923161e-07"/>
        <geom name="rs02_1_visual_0" class="visual" type="mesh" mesh="RS02_0_0_0"/>
        <geom name="rs02_1_collision_0" class="collision" type="mesh" mesh="RS02_0_0_0"/>
        <body name="joint1" pos="0 0 0" quat="1.326794897e-06 1 0 0">
          <inertial pos="1.03e-05 -0.0142659 0.0579402" mass="0.270398" fullinertia="0.00081368 0.00104368 0.00081949 0 0 0"/>
          <joint name="j1" type="hinge" axis="0 0 1" range="-3.14159 3.14159"/>
          <geom name="joint1_visual_0" class="visual" type="mesh" mesh="joint1"/>
          <geom name="joint1_collision_0" class="collision" type="mesh" mesh="joint1"/>
          <body name="rs03" pos="-0.0362 0 -0.0893" quat="0.4999981634 0.5 -0.5000018366 -0.5">
            <inertial pos="0 0 -0.0215" mass="0.9244" fullinertia="0.0008718102654 0.0009164494325 0.001195322212 -6.322401251e-07 -7.163998969e-06 -1.177125045e-06"/>
            <geom name="rs03_visual_0" class="visual" type="mesh" mesh="RS03_0_0_0"/>
            <geom name="rs03_collision_0" class="collision" type="mesh" mesh="RS03_0_0_0"/>
            <body name="link1_1" pos="0 0 0" quat="2.679489659e-08 1 0 0">
              <inertial pos="0 0.0121112 0.0430994" mass="0.236296" fullinertia="0.00039409 0.00035378 0.00043232 0 0 0"/>
              <joint name="j2" type="hinge" axis="0 0 1" range="-1.78 1.78"/>
              <geom name="link1_1_visual_0" class="visual" type="mesh" mesh="link1_1"/>
              <geom name="link1_1_collision_0" class="collision" type="mesh" mesh="link1_1"/>
              <body name="link1_2" pos="0 0.05 -0.05715" quat="0.7071054825 -0.7071080799 0 0">
                <inertial pos="0 0 0.15" mass="0.508299975" fullinertia="0.003890759307 0.003890759307 0.000157018996 0 0 0"/>
                <geom name="link1_2_visual_0" class="visual" type="mesh" mesh="link1_2"/>
                <geom name="link1_2_collision_0" class="collision" type="mesh" mesh="link1_2"/>
                <body name="link1_3" pos="0 0 0.3" quat="2.679489659e-08 0 0 1">
                  <inertial pos="2e-07 0.0155124 0.0339681" mass="0.279149934" fullinertia="0.000661231823 0.000687897169 0.000472960204 -1.55e-09 1.529e-09 0.000125413257"/>
                  <geom name="link1_3_visual_0" class="visual" type="mesh" mesh="link1_3"/>
                  <geom name="link1_3_collision_0" class="collision" type="mesh" mesh="link1_3"/>
                  <body name="rs02_2" pos="0 0.06735 0.05" quat="0.7071054825 -0.7071080799 0 0">
                    <inertial pos="0 0 -0.0183" mass="0.4116" fullinertia="0.0002744593935 0.0002739045499 0.0002868015076 -2.67562942e-08 -1.361358361e-08 -1.986923161e-07"/>
                    <geom name="rs02_2_visual_0" class="visual" type="mesh" mesh="RS02_0_0_0"/>
                    <geom name="rs02_2_collision_0" class="collision" type="mesh" mesh="RS02_0_0_0"/>
                    <body name="link2_1" pos="0 0 0" quat="0 2.679489659e-08 1 2.679489659e-08">
                      <inertial pos="3.1e-06 -0.0100157 0.0438699" mass="0.151798" fullinertia="0.00026036 0.00033758 0.00027115 0 0 0"/>
                      <joint name="j3" type="hinge" axis="0 0 1" range="-3.14159 3.14159"/>
                      <geom name="link2_1_visual_0" class="visual" type="mesh" mesh="link2_1"/>
                      <geom name="link2_1_collision_0" class="collision" type="mesh" mesh="link2_1"/>
                      <body name="link2_2" pos="0 -0.05 -0.07415" quat="0.7071054825 0.7071080799 0 0">
                        <inertial pos="3.54e-05 -3.54e-05 0.0291096" mass="0.112" fullinertia="9.821e-05 9.821e-05 0.00011208 0 0 0"/>
                        <geom name="link2_2_visual_0" class="visual" type="mesh" mesh="link2_2"/>
                        <geom name="link2_2_collision_0" class="collision" type="mesh" mesh="link2_2"/>
                        <body name="link2_3" pos="0 0 0.23" quat="1 0 0 0">
                          <inertial pos="0 0 0.115" mass="0.170500037" fullinertia="0.000759754048 0.000759754048 5.2564816e-05 0 0 0"/>
                          <geom name="link2_3_visual_0" class="visual" type="mesh" mesh="link2_3"/>
                          <geom name="link2_3_collision_0" class="collision" type="mesh" mesh="link2_3"/>
                          <body name="rs02_3" pos="0 -0.06585 0.05" quat="0.7071054825 0.7071080799 0 0">
                            <inertial pos="0 0 -0.0183" mass="0.4116" fullinertia="0.0002744593935 0.0002739045499 0.0002868015076 -2.67562942e-08 -1.361358361e-08 -1.986923161e-07"/>
                            <geom name="rs02_3_visual_0" class="visual" type="mesh" mesh="RS02_0_0_0"/>
                            <geom name="rs02_3_collision_0" class="collision" type="mesh" mesh="RS02_0_0_0"/>
                            <body name="link3_1" pos="0 0 0" quat="1.326794897e-06 0 1 0">
                              <inertial pos="0 0 0.115" mass="0.170500037" fullinertia="0.000759754048 0.000759754048 5.2564816e-05 0 0 0"/>
                              <joint name="j4" type="hinge" axis="0 0 1" range="-3.14159 3.14159"/>
                              <geom name="link3_1_visual_0" class="visual" type="mesh" mesh="link3_1"/>
                              <geom name="link3_1_collision_0" class="collision" type="mesh" mesh="link3_1"/>
                              <body name="rs00_1" pos="0 0.0724 -0.053" quat="0.7071054825 -0.7071080799 0 0">
                                <inertial pos="0 0 -0.0215" mass="0.9244" fullinertia="0.0008718102654 0.0009164494325 0.001195322212 -6.322401251e-07 -7.163998969e-06 -1.177125045e-06"/>
                                <geom name="rs00_1_visual_0" class="visual" type="mesh" mesh="RS00"/>
                                <geom name="rs00_1_collision_0" class="collision" type="mesh" mesh="RS00"/>
                                <body name="link3_2" pos="0 0 0" quat="1.326794897e-06 0 1 0">
                                  <inertial pos="0 0 0.115" mass="0.170500037" fullinertia="0.000759754048 0.000759754048 5.2564816e-05 0 0 0"/>
                                  <joint name="j5" type="hinge" axis="0 0 1" range="-3.14159 3.14159"/>
                                  <geom name="link3_2_visual_0" class="visual" type="mesh" mesh="link3_2"/>
                                  <geom name="link3_2_collision_0" class="collision" type="mesh" mesh="link3_2"/>
                                  <body name="rs00_2" pos="0 0.0724 -0.058" quat="0.7071054825 -0.7071080799 0 0">
                                    <inertial pos="0 0 -0.0215" mass="0.9244" fullinertia="0.0008718102654 0.0009164494325 0.001195322212 -6.322401251e-07 -7.163998969e-06 -1.177125045e-06"/>
                                    <geom name="rs00_2_visual_0" class="visual" type="mesh" mesh="RS00"/>
                                    <geom name="rs00_2_collision_0" class="collision" type="mesh" mesh="RS00"/>
                                    <body name="connect_00" pos="0 0 0" quat="3.267948965e-07 1 0 0">
                                      <inertial pos="0 0 0" mass="0.1" fullinertia="0.0001 0.0001 0.0001 0 0 0"/>
                                      <joint name="j6" type="hinge" axis="0 0 1" range="-3.14159 3.14159"/>
                                      <geom name="connect_00_visual_0" class="visual" type="mesh" mesh="connect_00"/>
                                      <geom name="connect_00_collision_0" class="collision" type="mesh" mesh="connect_00"/>
                                      <body name="connect_05" pos="0 0 -0.02" quat="3.267948965e-07 1 0 0">
                                        <inertial pos="0 0 0" mass="0.1" fullinertia="0.0001 0.0001 0.0001 0 0 0"/>
                                        <geom name="connect_05_visual_0" class="visual" type="mesh" mesh="connect_05"/>
                                        <geom name="connect_05_collision_0" class="collision" type="mesh" mesh="connect_05"/>
                                        <body name="rs05" pos="0 0 0.06" quat="1 0 0 0">
                                          <inertial pos="0 0 0" mass="0.9244" fullinertia="0.0008718102654 0.0009164494325 0.001195322212 -6.322401251e-07 -7.163998969e-06 -1.177125045e-06"/>
                                          <geom name="rs05_visual_0" class="visual" type="mesh" mesh="RS05"/>
                                          <geom name="rs05_collision_0" class="collision" type="mesh" mesh="RS05"/>
                                          <body name="case" pos="0 0 0" quat="1 0 0 0">
                                            <inertial pos="0 0 0" mass="0.1" fullinertia="0.0001 0.0001 0.0001 0 0 0"/>
                                            <geom name="case_visual_0" class="visual" type="mesh" mesh="case"/>
                                            <geom name="case_collision_0" class="collision" type="mesh" mesh="case"/>
                                          </body>
                                          <body name="gripper" pos="0 0 0" quat="1.326794897e-06 0 1 0">
                                            <inertial pos="0 0 0" mass="0.1" fullinertia="0.0001 0.0001 0.0001 0 0 0"/>
                                            <geom name="gripper_visual_0" class="visual" type="mesh" mesh="gripper"/>
                                            <geom name="gripper_collision_0" class="collision" type="mesh" mesh="gripper"/>
                                            <body name="finger_r" pos="0 -0.0625 -0.0198" quat="1 0 0 0">
                                              <inertial pos="0 0 0" mass="0.1" fullinertia="0.0001 0.0001 0.0001 0 0 0"/>
                                              <joint name="finger_r" type="slide" axis="0 1 0" range="0 0.05"/>
                                              <geom name="finger_r_visual_0" class="visual" type="mesh" mesh="finger_r"/>
                                              <geom name="finger_r_collision_0" class="collision" type="mesh" mesh="finger_r"/>
                                            </body>
                                            <body name="finger_l" pos="0 0.0625 -0.0198" quat="1 0 0 0">
                                              <inertial pos="0 0 0" mass="0.1" fullinertia="0.0001 0.0001 0.0001 0 0 0"/>
                                              <joint name="finger_l" type="slide" axis="0 -1 0" range="0 0.05"/>
                                              <geom name="finger_l_visual_0" class="visual" type="mesh" mesh="finger_l"/>
                                              <geom name="finger_l_collision_0" class="collision" type="mesh" mesh="finger_l"/>
                                            </body>
                                          </body>
                                        </body>
                                      </body>
                                    </body>
                                  </body>
                                </body>
                              </body>
                            </body>
                          </body>
                        </body>
                      </body>
                    </body>
                  </body>
                </body>
              </body>
            </body>
          </body>
        </body>
      </body>
    </body>
  </worldbody>
  <equality>
    <joint name="finger_l_mimic_finger_r" joint1="finger_l" joint2="finger_r" polycoef="0 1 0 0 0"/>
  </equality>
  <actuator>
    <motor name="j1_motor" joint="j1" gear="1" ctrllimited="true" ctrlrange="-50 50"/>
    <motor name="j2_motor" joint="j2" gear="1" ctrllimited="true" ctrlrange="-50 50"/>
    <motor name="j3_motor" joint="j3" gear="1" ctrllimited="true" ctrlrange="-50 50"/>
    <motor name="j4_motor" joint="j4" gear="1" ctrllimited="true" ctrlrange="-50 50"/>
    <motor name="j5_motor" joint="j5" gear="1" ctrllimited="true" ctrlrange="-50 50"/>
    <motor name="j6_motor" joint="j6" gear="1" ctrllimited="true" ctrlrange="-50 50"/>
    <motor name="finger_r_motor" joint="finger_r" gear="1" ctrllimited="true" ctrlrange="-50 50"/>
  </actuator>
  <keyframe>
    <key name="home" qpos="0 0 0 0 0 0 0 0" ctrl="0 0 0 0 0 0 0"/>
  </keyframe>
</mujoco>