<?xml version="1.0" encoding="utf-8"?>
<mujoco model="my_robot">
  <compiler angle="radian" meshdir="meshes" autolimits="true"/>
  <option gravity="0 0 -9.81" timestep="0.002"/>
  <size njmax="200" nconmax="200"/>
  <default>
    <joint damping="0.05" armature="0.001"/>
    <geom type="mesh" density="0" friction="1 0.005 0.0001"/>
  </default>
  <asset>
    <mesh name="base" file="base.stl" scale="0.001 0.001 0.001"/>
    <mesh name="RS02_000" file="RS02(0.0.0).stl" scale="0.001 0.001 0.001"/>
    <mesh name="RS03_000" file="RS03(0.0.0).stl" scale="0.001 0.001 0.001"/>
    <mesh name="RS00" file="RS00.stl" scale="0.001 0.001 0.001"/>
    <mesh name="RS05" file="RS05.stl" scale="0.001 0.001 0.001"/>
    <mesh name="joint1" file="joint1.stl" scale="0.001 0.001 0.001"/>
    <mesh name="link1_1" file="link1_1.stl" scale="0.001 0.001 0.001"/>
    <mesh name="link1_2" file="link1_2.stl" scale="0.001 0.001 0.001"/>
    <mesh name="link1_3" file="link1_3.stl" scale="0.001 0.001 0.001"/>
    <mesh name="link2_1" file="link2_1.stl" scale="0.001 0.001 0.001"/>
    <mesh name="link2_2" file="link2_2.stl" scale="0.001 0.001 0.001"/>
    <mesh name="link2_3" file="link2_3.stl" scale="0.001 0.001 0.001"/>
    <mesh name="link3_1" file="link3_1.stl" scale="0.001 0.001 0.001"/>
    <mesh name="link3_2" file="link3_2.stl" scale="0.001 0.001 0.001"/>
    <mesh name="link3_3" file="link3_3.stl" scale="0.001 0.001 0.001"/>
    <mesh name="gripper" file="gripper.stl" scale="0.001 0.001 0.001"/>
    <mesh name="finger_r" file="finger_r.stl" scale="0.001 0.001 0.001"/>
    <mesh name="finger_l" file="finger_l.stl" scale="0.001 0.001 0.001"/>
  </asset>
  <worldbody>
    <light name="top_light" pos="0 0 1.5" dir="0 0 -1" mode="trackcom"/>
    <camera name="front" pos="0.8 -1.2 0.7" xyaxes="1 0.5 0 -0.2 0.4 1"/>
    <body name="base">
      <inertial pos="-0.00000248163 0.000000483416 0.035385988818" mass="0.685513" fullinertia="0.002363000000 0.002295000000 0.003326000000 0.000000000000 0.000000000000 0.000000000000"/>
      <geom name="geom_base" mesh="base" contype="1" conaffinity="1"/>
      <body name="rs02_1" pos="0 0 0.1002" quat="1 0 0 0">
        <inertial pos="0 0 -0.0183" mass="0.411618" fullinertia="0.000201 0.000200 0.000287 0.000000 0.000000 0.000000"/>
        <geom name="geom_rs02_1" mesh="RS02_000" contype="1" conaffinity="1"/>
        <body name="joint1" pos="0 0 0" quat="0.000001326795 0.999999999999 0 0">
          <joint name="j1" type="hinge" axis="0 0 1" range="-3.14159 3.14159" limited="true" actuatorfrcrange="-50 50"/>
          <inertial pos="0.005674051863 0.000004286091 -0.057303043346" mass="0.431305" fullinertia="0.001623000000 0.001247000000 0.001062000000 0.000000000000 -0.000147000000 0.000000000000"/>
          <geom name="geom_joint1" mesh="joint1" contype="1" conaffinity="1"/>
          <body name="rs03" pos="-0.0362 0 -0.0893" quat="0.499998163397 0.499999999997 -0.500001836603 -0.499999999997">
            <inertial pos="0 0 -0.0215" mass="0.924357" fullinertia="0.000880 0.000920 0.001201 -0.000001 -0.000007 -0.000001"/>
            <geom name="geom_rs03" mesh="RS03_000" contype="1" conaffinity="1"/>
            <body name="link1_1" pos="0 0 0" quat="0.000000026795 1 0 0">
              <joint name="j2" type="hinge" axis="0 0 1" range="-1.78 1.78" limited="true" actuatorfrcrange="-50 50"/>
              <inertial pos="0.000000023649 0.022463093246 -0.0449012193" mass="0.350100" fullinertia="0.000685000000 0.000466000000 0.000710000000 0.000000000000 0.000000000000 0.000123000000"/>
              <geom name="geom_link1_1" mesh="link1_1" contype="1" conaffinity="1"/>
              <body name="link1_2" pos="0 0.05 -0.05715" quat="0.707105482511 -0.707108079859 0 0">
                <inertial pos="0.000001692897 -0.000002036842 0.15" mass="0.502204" fullinertia="0.003839000000 0.003839000000 0.000146000000 0.000000000000 0.000000000000 0.000000000000"/>
                <geom name="geom_link1_2" mesh="link1_2" contype="1" conaffinity="1"/>
                <body name="link1_3" pos="0 0 0.3" quat="0.000000026795 0 0 1">
                  <inertial pos="-0.000000306035 0.013487771767 0.021900262023" mass="0.279601" fullinertia="0.000662000000 0.000689000000 0.000476000000 -0.000002000000 -0.000002000000 -0.000126000000"/>
                  <geom name="geom_link1_3" mesh="link1_3" contype="1" conaffinity="1"/>
                  <body name="rs02_2" pos="0 0.06735 0.05" quat="0.707105482511 -0.707108079859 0 0">
                    <inertial pos="0 0 -0.0183" mass="0.411618" fullinertia="0.000201 0.000200 0.000287 0.000000 0.000000 0.000000"/>
                    <geom name="geom_rs02_2" mesh="RS02_000" contype="1" conaffinity="1"/>
                    <body name="link2_1" pos="0 0 0" quat="0.000000026795 1 0 0">
                      <joint name="j3" type="hinge" axis="0 0 1" range="-3.14159 3.14159" limited="true" actuatorfrcrange="-50 50"/>
                      <inertial pos="0.000566325368 -0.022115000982 -0.05767963311" mass="0.361563" fullinertia="0.000856000000 0.000639000000 0.000722000000 0.000010000000 0.000003000000 -0.000167000000"/>
                      <geom name="geom_link2_1" mesh="link2_1" contype="1" conaffinity="1"/>
                      <body name="link2_2" pos="0 -0.05 -0.07415" quat="0.707105482511 0.707108079859 0 0">
                        <inertial pos="0 0 0.115" mass="0.154772" fullinertia="0.000690000000 0.000690000000 0.000048000000 0.000000000000 0.000000000000 0.000000000000"/>
                        <geom name="geom_link2_2" mesh="link2_2" contype="1" conaffinity="1"/>
                        <body name="link2_3" pos="0 0 0.23" quat="1 0 0 0">
                          <inertial pos="0.000674605271 -0.012156717809 0.021127478899" mass="0.302349" fullinertia="0.000684000000 0.000702000000 0.000504000000 -0.000003000000 0.000008000000 0.000139000000"/>
                          <geom name="geom_link2_3" mesh="link2_3" contype="1" conaffinity="1"/>
                          <body name="rs02_3" pos="0 -0.06585 0.05" quat="0.707105482511 0.707108079859 0 0">
                            <inertial pos="0 0 -0.0183" mass="0.411618" fullinertia="0.000201 0.000200 0.000287 0.000000 0.000000 0.000000"/>
                            <geom name="geom_rs02_3" mesh="RS02_000" contype="1" conaffinity="1"/>
                            <body name="link3_1" pos="0 0 0" quat="0.000001326795 0 0.999999999999 0">
                              <joint name="j4" type="hinge" axis="0 0 1" range="-3.14159 3.14159" limited="true" actuatorfrcrange="-50 50"/>
                              <inertial pos="-0.000000154781 0.022689723837 -0.040161124828" mass="0.264011" fullinertia="0.000540000000 0.000493000000 0.000580000000 0.000000000000 0.000000000000 0.000101000000"/>
                              <geom name="geom_link3_1" mesh="link3_1" contype="1" conaffinity="1"/>
                              <body name="rs00_1" pos="0 0.0724 -0.053" quat="0.707105482511 -0.707108079859 0 0">
                                <inertial pos="0 0 -0.0208" mass="0.311841" fullinertia="0.000130 0.000129 0.000127 0.000000 0.000000 0.000000"/>
                                <geom name="geom_rs00_1" mesh="RS00" contype="1" conaffinity="1"/>
                                <body name="link3_2" pos="0 0 0" quat="0.000001326795 0 0.999999999999 0">
                                  <joint name="j5" type="hinge" axis="0 0 1" range="-3.14159 3.14159" limited="true" actuatorfrcrange="-50 50"/>
                                  <inertial pos="-0.000001870544 0.023210308078 -0.045745385269" mass="0.259261" fullinertia="0.000535000000 0.000491000000 0.000579000000 0.000000000000 0.000000000000 0.000098000000"/>
                                  <geom name="geom_link3_2" mesh="link3_2" contype="1" conaffinity="1"/>
                                  <body name="rs00_2" pos="0 0.0724 -0.058" quat="0.707105482511 -0.707108079859 0 0">
                                    <inertial pos="0 0 -0.0208" mass="0.311841" fullinertia="0.000130 0.000129 0.000127 0.000000 0.000000 0.000000"/>
                                    <geom name="geom_rs00_2" mesh="RS00" contype="1" conaffinity="1"/>
                                    <body name="link3_3" pos="0 0 0" quat="0 1 0 0">
                                      <joint name="j6" type="hinge" axis="0 0 1" range="-3.14159 3.14159" limited="true" actuatorfrcrange="-50 50"/>
                                      <inertial pos="-0.00000028707 0.001356284705 -0.050392020362" mass="0.202651" fullinertia="0.000305000000 0.000348000000 0.000343000000 0.000000000000 0.000000000000 -0.000010000000"/>
                                      <geom name="geom_link3_3" mesh="link3_3" contype="1" conaffinity="1"/>
                                      <body name="rs05" pos="0 0 -0.093" quat="0.00000023108 -0.707104897878 0.70710866449 0.000000231078">
                                        <inertial pos="0 0 -0.0183" mass="0.191090" fullinertia="0.000082 0.000082 0.000068 0.000000 0.000000 0.000000"/>
                                        <geom name="geom_rs05" mesh="RS05" contype="1" conaffinity="1"/>
                                        <body name="gripper" pos="0 0 0" quat="0.000001326795 0 0.999999999999 0">
                                          <inertial pos="-0.000001543486 -0.00000289698 -0.012058477856" mass="0.090928" fullinertia="0.000134000000 0.000013000000 0.000138000000 0.000006000000 0.000000000000 0.000000000000"/>
                                          <geom name="geom_gripper" mesh="gripper" contype="1" conaffinity="1"/>
                                          <body name="finger_r" pos="0 -0.06475 -0.0218" quat="1 0 0 0">
                                            <joint name="finger_r" type="slide" axis="0 1 0" range="0 0.0447" limited="true" actuatorfrcrange="-50 50"/>
                                            <inertial pos="0.000927864812 0.006622883789 -0.011071668038" mass="0.030964" fullinertia="0.000011000000 0.000012000000 0.000006000000 0.000000000000 0.000000000000 0.000003000000"/>
                                            <geom name="geom_finger_r" mesh="finger_r" contype="1" conaffinity="1"/>
                                          </body>
                                          <body name="finger_l" pos="0 0.06475 -0.0218" quat="1 0 0 0">
                                            <joint name="finger_l" type="slide" axis="0 -1 0" range="0 0.05" limited="true" actuatorfrcrange="-50 50"/>
                                            <inertial pos="-0.000922783846 -0.006622999429 -0.011071668038" mass="0.030964" fullinertia="0.000011000000 0.000012000000 0.000006000000 0.000000000000 0.000000000000 -0.000003000000"/>
                                            <geom name="geom_finger_l" mesh="finger_l" contype="1" conaffinity="1"/>
                                          </body>
                                        </body>
                                      </body>
                                    </body>
                                  </body>
                                </body>
                              </body>
                            </body>
                          </body>
                        </body>
                      </body>
                    </body>
                  </body>
                </body>
              </body>
            </body>
          </body>
        </body>
      </body>
    </body>
  </worldbody>
  <equality>
    <joint name="mimic_finger_l" joint1="finger_l" joint2="finger_r" polycoef="0 1 0 0 0"/>
  </equality>
  <actuator>
    <motor name="act_j1" joint="j1" gear="1" ctrlrange="-50 50"/>
    <motor name="act_j2" joint="j2" gear="1" ctrlrange="-50 50"/>
    <motor name="act_j3" joint="j3" gear="1" ctrlrange="-50 50"/>
    <motor name="act_j4" joint="j4" gear="1" ctrlrange="-50 50"/>
    <motor name="act_j5" joint="j5" gear="1" ctrlrange="-50 50"/>
    <motor name="act_j6" joint="j6" gear="1" ctrlrange="-50 50"/>
    <motor name="act_finger_r" joint="finger_r" gear="1" ctrlrange="-50 50"/>
  </actuator>
</mujoco>